import { render, screen } from '@testing-library/react';
import { describe, it, expect, beforeEach, afterEach, vi } from 'vitest';
import ErrorBoundary from './ErrorBoundary';
import '@testing-library/jest-dom';

// Test component that throws an error
const ThrowError = ({ shouldThrow = false }: { shouldThrow?: boolean }) => {
  if (shouldThrow) {
    throw new Error('Test error');
  }
  return <div>No error</div>;
};

// Mock logger
vi.mock('../utils/logger', () => ({
  logger: {
    error: vi.fn(),
    debug: vi.fn(),
  },
}));

describe('ErrorBoundary', () => {
  beforeEach(() => {
    // Suppress console.error for these tests since we're intentionally throwing errors
    vi.spyOn(console, 'error').mockImplementation(() => {});
  });

  afterEach(() => {
    vi.restoreAllMocks();
  });

  it('renders children when there is no error', () => {
    render(
      <ErrorBoundary>
        <ThrowError shouldThrow={false} />
      </ErrorBoundary>,
    );

    expect(screen.getByText('No error')).toBeInTheDocument();
  });

  it('renders default error UI when child component throws', () => {
    render(
      <ErrorBoundary>
        <ThrowError shouldThrow={true} />
      </ErrorBoundary>,
    );

    expect(screen.getByText('ðŸš¨ Something went wrong')).toBeInTheDocument();
    expect(
      screen.getByText(/An unexpected error occurred/),
    ).toBeInTheDocument();
    expect(
      screen.getByRole('button', { name: 'Try Again' }),
    ).toBeInTheDocument();
    expect(
      screen.getByRole('button', { name: 'Reload Page' }),
    ).toBeInTheDocument();
  });

  it('renders custom fallback UI when provided', () => {
    const customFallback = <div>Custom error message</div>;

    render(
      <ErrorBoundary fallback={customFallback}>
        <ThrowError shouldThrow={true} />
      </ErrorBoundary>,
    );

    expect(screen.getByText('Custom error message')).toBeInTheDocument();
    expect(
      screen.queryByText('ðŸš¨ Something went wrong'),
    ).not.toBeInTheDocument();
  });

  it('calls onError callback when error occurs', () => {
    const onError = vi.fn();

    render(
      <ErrorBoundary onError={onError}>
        <ThrowError shouldThrow={true} />
      </ErrorBoundary>,
    );

    expect(onError).toHaveBeenCalledWith(
      expect.objectContaining({ message: 'Test error' }),
      expect.objectContaining({ componentStack: expect.any(String) }),
    );
  });

  it('shows error details in development mode', () => {
    render(
      <ErrorBoundary>
        <ThrowError shouldThrow={true} />
      </ErrorBoundary>,
    );

    // In test environment, we should see error details
    expect(
      screen.getByText('Error Details (Development Only)'),
    ).toBeInTheDocument();
  });
});
